Workbook

Sheet Monthly P&L
A1: MED SPA PROFIT & LOSS STATEMENT
A2: Practice Name: | I2: Year: | K2: 2025
A3: ⚪ Blue text = enter your data ⚫ Black text = formula (do not edit)
A5: CATEGORY | B5: Jan | C5: Feb | D5: Mar | E5: Apr | F5: May | G5: Jun | H5: Jul | I5: Aug | J5: Sep | K5: Oct | L5: Nov | M5: Dec | N5: ANNUAL TOTAL | O5: MONTHLY AVG | P5: BENCHMARK
A7: REVENUE
A8: Injectable Revenue | N8: =SUM(B8:M8) | O8: =IF(N8=0,"-",N8/12)
A9: Energy-Based Device Revenue | N9: =SUM(B9:M9) | O9: =IF(N9=0,"-",N9/12)
A10: Esthetic Services Revenue | N10: =SUM(B10:M10) | O10: =IF(N10=0,"-",N10/12)
A11: Wellness Services Revenue | N11: =SUM(B11:M11) | O11: =IF(N11=0,"-",N11/12)
A12: Retail Sales Revenue | N12: =SUM(B12:M12) | O12: =IF(N12=0,"-",N12/12)
A13: Membership Revenue | N13: =SUM(B13:M13) | O13: =IF(N13=0,"-",N13/12)
A14: Other Revenue | N14: =SUM(B14:M14) | O14: =IF(N14=0,"-",N14/12)
A15: TOTAL REVENUE | B15: =SUM(B8:B14) | C15: =SUM(C8:C14) | D15: =SUM(D8:D14) | E15: =SUM(E8:E14) | F15: =SUM(F8:F14) | G15: =SUM(G8:G14) | H15: =SUM(H8:H14) | I15: =SUM(I8:I14) | ... M15: =SUM(M8:M14) | N15: =SUM(B15:M15) | O15: =IF(N15=0,"-",N15/12)
A17: COST OF GOODS SOLD (COGS)
A18: Injectable Costs | N18: =SUM(B18:M18) | O18: =IF(N18=0,"-",N18/12)
A19: Device Consumables | N19: =SUM(B19:M19) | O19: =IF(N19=0,"-",N19/12)
A20: Retail Product Costs | N20: =SUM(B20:M20) | O20: =IF(N20=0,"-",N20/12)
A21: Medical Supplies | N21: =SUM(B21:M21) | O21: =IF(N21=0,"-",N21/12)
A22: TOTAL COGS | B22: =SUM(B18:B21) | C22: =SUM(C18:C21) | D22: =SUM(D18:D21) | E22: =SUM(E18:E21) | F22: =SUM(F18:F21) | G22: =SUM(G18:G21) | H22: =SUM(H18:H21) | I22: =SUM(I18:I21) | ... M22: =SUM(M18:M21) | N22: =SUM(B22:M22) | O22: =IF(N22=0,"-",N22/12)
A24: GROSS PROFIT | B24: =B15-B22 | C24: =C15-C22 | D24: =D15-D22 | E24: =E15-E22 | F24: =F15-F22 | G24: =G15-G22 | H24: =H15-H22 | I24: =I15-I22 | ... M24: =M15-M22 | N24: =SUM(B24:M24) | O24: =IF(N24=0,"-",N24/12)
A25: Gross Margin % | B25: =IF(B15=0,"-",B24/B15) | C25: =IF(C15=0,"-",C24/C15) | D25: =IF(D15=0,"-",D24/D15) | E25: =IF(E15=0,"-",E24/E15) | F25: =IF(F15=0,"-",F24/F15) | G25: =IF(G15=0,"-",G24/G15) | H25: =IF(H15=0,"-",H24/H15) | I25: =IF(I15=0,"-",I24/I15) | ... N25: =IF(N15=0,"-",N24/N15) | P25: Goal: 70–80%
A27: PAYROLL
A28: Provider Compensation | N28: =SUM(B28:M28)
A29: Administrative Staff | N29: =SUM(B29:M29)
A30: Payroll Taxes | N30: =SUM(B30:M30)
A31: Benefits | N31: =SUM(B31:M31)
A32: TOTAL PAYROLL | B32: =SUM(B28:B31) | C32: =SUM(C28:C31) | D32: =SUM(D28:D31) | E32: =SUM(E28:E31) | F32: =SUM(F28:F31) | G32: =SUM(G28:G31) | H32: =SUM(H28:H31) | I32: =SUM(I28:I31) | ... M32: =SUM(M28:M31) | N32: =SUM(B32:M32)
A33: Payroll % of Revenue | B33: =IF(B15=0,"-",B32/B15) | C33: =IF(C15=0,"-",C32/C15) | D33: =IF(D15=0,"-",D32/D15) | E33: =IF(E15=0,"-",E32/E15) | F33: =IF(F15=0,"-",F32/F15) | G33: =IF(G15=0,"-",G32/G15) | H33: =IF(H15=0,"-",H32/H15) | I33: =IF(I15=0,"-",I32/I15) | ... N33: =IF(N15=0,"-",N32/N15) | P33: Goal: 25–35%
A35: MARKETING
A36: Digital Advertising (Meta / Google / TikTok) | N36: =SUM(B36:M36)
A37: Agency Fees | N37: =SUM(B37:M37)
A38: Website & SEO | N38: =SUM(B38:M38)
A39: CRM Platforms | N39: =SUM(B39:M39)
A40: Photography & Content | N40: =SUM(B40:M40)
A41: Print Materials | N41: =SUM(B41:M41)
A42: TOTAL MARKETING | B42: =SUM(B36:B41) | C42: =SUM(C36:C41) | D42: =SUM(D36:D41) | E42: =SUM(E36:E41) | F42: =SUM(F36:F41) | G42: =SUM(G36:G41) | H42: =SUM(H36:H41) | I42: =SUM(I36:I41) | ... M42: =SUM(M36:M41) | N42: =SUM(B42:M42)
A43: Marketing % of Revenue | B43: =IF(B15=0,"-",B42/B15) | C43: =IF(C15=0,"-",C42/C15) | D43: =IF(D15=0,"-",D42/D15) | E43: =IF(E15=0,"-",E42/E15) | F43: =IF(F15=0,"-",F42/F15) | G43: =IF(G15=0,"-",G42/G15) | H43: =IF(H15=0,"-",H42/H15) | I43: =IF(I15=0,"-",I42/I15) | ... N43: =IF(N15=0,"-",N42/N15) | P43: Goal: 5–10%
A45: OCCUPANCY
A46: Rent | N46: =SUM(B46:M46)
A47: CAM Fees | N47: =SUM(B47:M47)
...

Sheet Revenue by Service
A1: REVENUE BY SERVICE
A2: Enter amounts in each service line. Totals reconcile to Monthly P&L tab.
A4: SERVICE / CATEGORY | B4: Jan | C4: Feb | D4: Mar | E4: Apr | F4: May | G4: Jun | H4: Jul | I4: Aug | J4: Sep | K4: Oct | L4: Nov | M4: Dec | N4: ANNUAL TOTAL
A6: INJECTABLES
A7: Botox / Nuceiva | N7: =SUM(B7:M7)
A8: Dysport / Xeomin / Daxxify | N8: =SUM(B8:M8)
A9: Dermal Fillers | N9: =SUM(B9:M9)
A10: Sculptra / Radiesse | N10: =SUM(B10:M10)
A11: PRF / PRP | N11: =SUM(B11:M11)
A12: INJECTABLES TOTAL | B12: =SUM(B7:B11) | C12: =SUM(C7:C11) | D12: =SUM(D7:D11) | E12: =SUM(E7:E11) | F12: =SUM(F7:F11) | G12: =SUM(G7:G11) | H12: =SUM(H7:H11) | I12: =SUM(I7:I11) | ... N12: =SUM(N7:N11)
A14: ENERGY-BASED DEVICES
A15: Morpheus8 | N15: =SUM(B15:M15)
A16: Lumecca (IPL) | N16: =SUM(B16:M16)
A17: Forma (RF) | N17: =SUM(B17:M17)
A18: Diolaze (Laser Hair Removal) | N18: =SUM(B18:M18)
A19: BodyTite / FaceTite | N19: =SUM(B19:M19)
A20: Other Devices | N20: =SUM(B20:M20)
A21: ENERGY-BASED DEVICES TOTAL | B21: =SUM(B15:B20) | C21: =SUM(C15:C20) | D21: =SUM(D15:D20) | E21: =SUM(E15:E20) | F21: =SUM(F15:F20) | G21: =SUM(G15:G20) | H21: =SUM(H15:H20) | I21: =SUM(I15:I20) | ... N21: =SUM(N15:N20)
A23: ESTHETIC SERVICES
A24: Facials | N24: =SUM(B24:M24)
A25: Chemical Peels | N25: =SUM(B25:M25)
A26: HydraFacial | N26: =SUM(B26:M26)
A27: Dermaplaning | N27: =SUM(B27:M27)
A28: Microneedling | N28: =SUM(B28:M28)
A29: ESTHETIC SERVICES TOTAL | B29: =SUM(B24:B28) | C29: =SUM(C24:C28) | D29: =SUM(D24:D28) | E29: =SUM(E24:E28) | F29: =SUM(F24:F28) | G29: =SUM(G24:G28) | H29: =SUM(H24:H28) | I29: =SUM(I24:I28) | ... N29: =SUM(N24:N28)
A31: WELLNESS SERVICES
A32: Medical Weight Loss | N32: =SUM(B32:M32)
A33: IV Therapy | N33: =SUM(B33:M33)
A34: Hormone Optimization | N34: =SUM(B34:M34)
A35: Sexual Wellness | N35: =SUM(B35:M35)
A36: WELLNESS SERVICES TOTAL | B36: =SUM(B32:B35) | C36: =SUM(C32:C35) | D36: =SUM(D32:D35) | E36: =SUM(E32:E35) | F36: =SUM(F32:F35) | G36: =SUM(G32:G35) | H36: =SUM(H32:H35) | I36: =SUM(I32:I35) | ... N36: =SUM(N32:N35)
A38: RETAIL SALES
A39: Skincare Products | N39: =SUM(B39:M39)
A40: Supplements | N40: =SUM(B40:M40)
A41: Other Retail | N41: =SUM(B41:M41)
A42: RETAIL SALES TOTAL | B42: =SUM(B39:B41) | C42: =SUM(C39:C41) | D42: =SUM(D39:D41) | E42: =SUM(E39:E41) | F42: =SUM(F39:F41) | G42: =SUM(G39:G41) | H42: =SUM(H39:H41) | I42: =SUM(I39:I41) | ... N42: =SUM(N39:N41)
A44: MEMBERSHIPS
A45: Monthly Membership Fees | N45: =SUM(B45:M45)
A46: VIP Programs | N46: =SUM(B46:M46)
A47: MEMBERSHIPS TOTAL | B47: =SUM(B45:B46) | C47: =SUM(C45:C46) | D47: =SUM(D45:D46) | E47: =SUM(E45:E46) | F47: =SUM(F45:F46) | G47: =SUM(G45:G46) | H47: =SUM(H45:H46) | I47: =SUM(I45:I46) | ... N47: =SUM(N45:N46)
...

Sheet Revenue by Provider
A1: REVENUE BY PROVIDER
A2: Enter monthly revenue per provider. % of Total calculates automatically.
A4: PROVIDER | B4: Jan | C4: Feb | D4: Mar | E4: Apr | F4: May | G4: Jun | H4: Jul | I4: Aug | J4: Sep | K4: Oct | L4: Nov | M4: Dec | N4: ANNUAL TOTAL | O4: % OF TOTAL
A6: Provider A | N6: =SUM(B6:M6) | O6: =IF(N10=0,"-",N6/N10)
A7: Provider B | N7: =SUM(B7:M7) | O7: =IF(N10=0,"-",N7/N10)
A8: Provider C | N8: =SUM(B8:M8) | O8: =IF(N10=0,"-",N8/N10)
A9: Provider D | N9: =SUM(B9:M9) | O9: =IF(N10=0,"-",N9/N10)
A10: TOTAL ALL PROVIDERS | B10: =SUM(B6:B9) | C10: =SUM(C6:C9) | D10: =SUM(D6:D9) | E10: =SUM(E6:E9) | F10: =SUM(F6:F9) | G10: =SUM(G6:G9) | H10: =SUM(H6:H9) | I10: =SUM(I6:I9) | ... N10: =SUM(N6:N9) | O10: 100.0%
A12: Revenue Per Provider: | D12: =IF(COUNTA(A6:A9)=0,"-",N10/COUNTA(A6:A9))

Sheet KPI Dashboard
A1: KPI DASHBOARD
A2: Metrics auto-calculate from Monthly P&L. Green = on track · Yellow = watch · Red = needs attention.
A4: # of Treatment Rooms: | D4: 3
A6: KPI METRIC | B6: GOAL | C6: Jan | D6: Feb | E6: Mar | F6: Apr | G6: May | H6: Jun | I6: Jul | J6: Aug | K6: Sep | L6: Oct | M6: Nov | N6: Dec | O6: YTD
A8: Total Revenue ($) | B8: - | C8: ='Monthly P&L'!B15 | D8: ='Monthly P&L'!C15 | E8: ='Monthly P&L'!D15 | F8: ='Monthly P&L'!E15 | G8: ='Monthly P&L'!F15 | H8: ='Monthly P&L'!G15 | I8: ='Monthly P&L'!H15 | J8: ='Monthly P&L'!I15 | ... O8: ='Monthly P&L'!N15
A9: Gross Margin % | B9: 70–80% | C9: =IF('Monthly P&L'!B15=0,"-",'Monthly P&L'!B24/'Monthly P&L'!B15) | D9: =IF('Monthly P&L'!C15=0,"-",'Monthly P&L'!C24/'Monthly P&L'!C15) | E9: =IF('Monthly P&L'!D15=0,"-",'Monthly P&L'!D24/'Monthly P&L'!D15) | F9: =IF('Monthly P&L'!E15=0,"-",'Monthly P&L'!E24/'Monthly P&L'!E15) | G9: =IF('Monthly P&L'!F15=0,"-",'Monthly P&L'!F24/'Monthly P&L'!F15) | H9: =IF('Monthly P&L'!G15=0,"-",'Monthly P&L'!G24/'Monthly P&L'!G15) | I9: =IF('Monthly P&L'!H15=0,"-",'Monthly P&L'!H24/'Monthly P&L'!H15) | J9: =IF('Monthly P&L'!I15=0,"-",'Monthly P&L'!I24/'Monthly P&L'!I15) | ... O9: =IF('Monthly P&L'!N15=0,"-",'Monthly P&L'!N24/'Monthly P&L'!N15)
A10: Payroll % of Revenue | B10: 25–35% | C10: =IF('Monthly P&L'!B15=0,"-",'Monthly P&L'!B32/'Monthly P&L'!B15) | D10: =IF('Monthly P&L'!C15=0,"-",'Monthly P&L'!C32/'Monthly P&L'!C15) | E10: =IF('Monthly P&L'!D15=0,"-",'Monthly P&L'!D32/'Monthly P&L'!D15) | F10: =IF('Monthly P&L'!E15=0,"-",'Monthly P&L'!E32/'Monthly P&L'!E15) | G10: =IF('Monthly P&L'!F15=0,"-",'Monthly P&L'!F32/'Monthly P&L'!F15) | H10: =IF('Monthly P&L'!G15=0,"-",'Monthly P&L'!G32/'Monthly P&L'!G15) | I10: =IF('Monthly P&L'!H15=0,"-",'Monthly P&L'!H32/'Monthly P&L'!H15) | J10: =IF('Monthly P&L'!I15=0,"-",'Monthly P&L'!I32/'Monthly P&L'!I15) | ... O10: =IF('Monthly P&L'!N15=0,"-",'Monthly P&L'!N32/'Monthly P&L'!N15)
A11: Marketing % of Revenue | B11: 5–10% | C11: =IF('Monthly P&L'!B15=0,"-",'Monthly P&L'!B42/'Monthly P&L'!B15) | D11: =IF('Monthly P&L'!C15=0,"-",'Monthly P&L'!C42/'Monthly P&L'!C15) | E11: =IF('Monthly P&L'!D15=0,"-",'Monthly P&L'!D42/'Monthly P&L'!D15) | F11: =IF('Monthly P&L'!E15=0,"-",'Monthly P&L'!E42/'Monthly P&L'!E15) | G11: =IF('Monthly P&L'!F15=0,"-",'Monthly P&L'!F42/'Monthly P&L'!F15) | H11: =IF('Monthly P&L'!G15=0,"-",'Monthly P&L'!G42/'Monthly P&L'!G15) | I11: =IF('Monthly P&L'!H15=0,"-",'Monthly P&L'!H42/'Monthly P&L'!H15) | J11: =IF('Monthly P&L'!I15=0,"-",'Monthly P&L'!I42/'Monthly P&L'!I15) | ... O11: =IF('Monthly P&L'!N15=0,"-",'Monthly P&L'!N42/'Monthly P&L'!N15)
A12: Occupancy % of Revenue | B12: 10–15% | C12: =IF('Monthly P&L'!B15=0,"-",'Monthly P&L'!B50/'Monthly P&L'!B15) | D12: =IF('Monthly P&L'!C15=0,"-",'Monthly P&L'!C50/'Monthly P&L'!C15) | E12: =IF('Monthly P&L'!D15=0,"-",'Monthly P&L'!D50/'Monthly P&L'!D15) | F12: =IF('Monthly P&L'!E15=0,"-",'Monthly P&L'!E50/'Monthly P&L'!E15) | G12: =IF('Monthly P&L'!F15=0,"-",'Monthly P&L'!F50/'Monthly P&L'!F15) | H12: =IF('Monthly P&L'!G15=0,"-",'Monthly P&L'!G50/'Monthly P&L'!G15) | I12: =IF('Monthly P&L'!H15=0,"-",'Monthly P&L'!H50/'Monthly P&L'!H15) | J12: =IF('Monthly P&L'!I15=0,"-",'Monthly P&L'!I50/'Monthly P&L'!I15) | ... O12: =IF('Monthly P&L'!N15=0,"-",'Monthly P&L'!N50/'Monthly P&L'!N15)
A13: Net Profit % of Revenue | B13: 15–30% | C13: =IF('Monthly P&L'!B15=0,"-",'Monthly P&L'!B64/'Monthly P&L'!B15) | D13: =IF('Monthly P&L'!C15=0,"-",'Monthly P&L'!C64/'Monthly P&L'!C15) | E13: =IF('Monthly P&L'!D15=0,"-",'Monthly P&L'!D64/'Monthly P&L'!D15) | F13: =IF('Monthly P&L'!E15=0,"-",'Monthly P&L'!E64/'Monthly P&L'!E15) | G13: =IF('Monthly P&L'!F15=0,"-",'Monthly P&L'!F64/'Monthly P&L'!F15) | H13: =IF('Monthly P&L'!G15=0,"-",'Monthly P&L'!G64/'Monthly P&L'!G15) | I13: =IF('Monthly P&L'!H15=0,"-",'Monthly P&L'!H64/'Monthly P&L'!H15) | J13: =IF('Monthly P&L'!I15=0,"-",'Monthly P&L'!I64/'Monthly P&L'!I15) | ... O13: =IF('Monthly P&L'!N15=0,"-",'Monthly P&L'!N64/'Monthly P&L'!N15)
A14: Revenue Per Provider ($) | B14: - | C14: =IF('Revenue by Provider'!N10=0,"-",'Revenue by Provider'!B10/IF(COUNTA('Revenue by Provider'!A6:A9)=0,1,COUNTA('Revenue by Provider'!A6:A9))) | D14: =IF('Revenue by Provider'!N10=0,"-",'Revenue by Provider'!C10/IF(COUNTA('Revenue by Provider'!A6:A9)=0,1,COUNTA('Revenue by Provider'!A6:A9))) | E14: =IF('Revenue by Provider'!N10=0,"-",'Revenue by Provider'!D10/IF(COUNTA('Revenue by Provider'!A6:A9)=0,1,COUNTA('Revenue by Provider'!A6:A9))) | F14: =IF('Revenue by Provider'!N10=0,"-",'Revenue by Provider'!E10/IF(COUNTA('Revenue by Provider'!A6:A9)=0,1,COUNTA('Revenue by Provider'!A6:A9))) | G14: =IF('Revenue by Provider'!N10=0,"-",'Revenue by Provider'!F10/IF(COUNTA('Revenue by Provider'!A6:A9)=0,1,COUNTA('Revenue by Provider'!A6:A9))) | H14: =IF('Revenue by Provider'!N10=0,"-",'Revenue by Provider'!G10/IF(COUNTA('Revenue by Provider'!A6:A9)=0,1,COUNTA('Revenue by Provider'!A6:A9))) | I14: =IF('Revenue by Provider'!N10=0,"-",'Revenue by Provider'!H10/IF(COUNTA('Revenue by Provider'!A6:A9)=0,1,COUNTA('Revenue by Provider'!A6:A9))) | J14: =IF('Revenue by Provider'!N10=0,"-",'Revenue by Provider'!I10/IF(COUNTA('Revenue by Provider'!A6:A9)=0,1,COUNTA('Revenue by Provider'!A6:A9))) | K14: =IF('Revenue by Provider'!N10=0,"-",'Revenue by Provider'!J10/IF(COUNTA('Revenue by Provider'!A6:A9)=0,1,COUNTA('Revenue by Provider'!A6:A9))) | L14: =IF('Revenue by Provider'!N10=0,"-",'Revenue by Provider'!K10/IF(COUNTA('Revenue by Provider'!A6:A9)=0,1,COUNTA('Revenue by Provider'!A6:A9))) | M14: =IF('Revenue by Provider'!N10=0,"-",'Revenue by Provider'!L10/IF(COUNTA('Revenue by Provider'!A6:A9)=0,1,COUNTA('Revenue by Provider'!A6:A9))) | N14: =IF('Revenue by Provider'!N10=0,"-",'Revenue by Provider'!M10/IF(COUNTA('Revenue by Provider'!A6:A9)=0,1,COUNTA('Revenue by Provider'!A6:A9))) | O14: =IF('Revenue by Provider'!N10=0,"-",'Revenue by Provider'!N10/IF(COUNTA('Revenue by Provider'!A6:A9)=0,1,COUNTA('Revenue by Provider'!A6:A9)))
A15: Revenue Per Treatment Room | B15: (÷Rooms) | C15: =IF('Monthly P&L'!B15=0,"-",'Monthly P&L'!B15/$D$4) | D15: =IF('Monthly P&L'!C15=0,"-",'Monthly P&L'!C15/$D$4) | E15: =IF('Monthly P&L'!D15=0,"-",'Monthly P&L'!D15/$D$4) | F15: =IF('Monthly P&L'!E15=0,"-",'Monthly P&L'!E15/$D$4) | G15: =IF('Monthly P&L'!F15=0,"-",'Monthly P&L'!F15/$D$4) | H15: =IF('Monthly P&L'!G15=0,"-",'Monthly P&L'!G15/$D$4) | I15: =IF('Monthly P&L'!H15=0,"-",'Monthly P&L'!H15/$D$4) | J15: =IF('Monthly P&L'!I15=0,"-",'Monthly P&L'!I15/$D$4) | ... O15: =IF('Monthly P&L'!N15=0,"-",'Monthly P&L'!N15/$D$4)
A16: Net Operating Profit ($) | B16: - | C16: ='Monthly P&L'!B64 | D16: ='Monthly P&L'!C64 | E16: ='Monthly P&L'!D64 | F16: ='Monthly P&L'!E64 | G16: ='Monthly P&L'!F64 | H16: ='Monthly P&L'!G64 | I16: ='Monthly P&L'!H64 | J16: ='Monthly P&L'!I64 | ... O16: ='Monthly P&L'!N64
A18: COLOR KEY
A19: Blue text = Input (enter your data)
A20: Black text = Formula (auto-calculates)
A21: Green text = Cross-sheet reference
A22: Green background = Benchmark / Goal
A23: Gold background = Key input assumption
